<mujoco model="2dof_arm">
  <compiler angle="radian" />

  <option timestep="0.001" gravity="0 0 -9.81" />

  <default>
    <joint damping="0.1" armature="0.01" />
    <geom contype="1" conaffinity="1" />
  </default>

  <worldbody>
    <!-- Fixed base -->
    <body name="base" pos="0 0 0">
      <geom type="box" size="0.05 0.05 0.02" rgba="0.3 0.3 0.3 1" mass="0.1" />

      <!-- Link 1: Shoulder to elbow (10cm) -->
      <body name="link1" pos="0 0 0.02">
        <joint name="shoulder" type="hinge" axis="0 0 1"
               range="-1.57 1.57" damping="0.1" />
        <geom type="capsule" size="0.015 0.05" rgba="0.8 0.2 0.2 1"
              pos="0.05 0 0" quat="0.707 0 0.707 0" mass="0.02" />

        <!-- Link 2: Elbow to end-effector (8cm) -->
        <body name="link2" pos="0.1 0 0">
          <joint name="elbow" type="hinge" axis="0 1 0"
                 range="-1.57 1.57" damping="0.08" />
          <geom type="capsule" size="0.012 0.04" rgba="0.2 0.8 0.2 1"
                pos="0.04 0 0" quat="0.707 0 0.707 0" mass="0.015" />

          <!-- End effector -->
          <body name="end_effector" pos="0.08 0 0">
            <geom type="sphere" size="0.01" rgba="0.2 0.2 0.8 1" mass="0.005" />

            <!-- IMU sensor location (visualization) -->
            <site name="imu" pos="0 0 0" size="0.005" rgba="1 1 0 1" />
          </body>
        </body>
      </body>
    </body>
  </worldbody>

  <actuator>
    <!-- Position servos (modeling SG90 behavior) -->
    <position name="shoulder_servo" joint="shoulder" kp="2.0" />
    <position name="elbow_servo" joint="elbow" kp="2.0" />
  </actuator>

  <sensor>
    <jointpos name="shoulder_pos" joint="shoulder" />
    <jointpos name="elbow_pos" joint="elbow" />
    <framequat name="imu_quat" objtype="site" objname="imu" />
  </sensor>
</mujoco>
